Workbook
Name Slicer_Borough: #N/A

Sheet Results
A1: The Cost of Living in London: Affordability Across Boroughs by Rent, Income, and Transport
A2: Introduction
A3: This project investigates housing affordability in London at the borough level. Using income, rent, council tax, and transport accessibility data, I developed an Overall Affordability Index that measures the share of gross income required to cover essential living costs.
A4: The analysis examines differences by gender, employment type, and household structure, and explores the trade-off between affordability and commuting time.
A5: Data & Methodology
A6: Income Data: Weekly pay by borough (overall, male, female, part-time, full-time).
A7: Housing Data: Median rents by bedroom category (room, studio, 1–3 bed).
A8: Council Tax: Borough-level band data, mapped to property sizes.
A9: Transport: Average commuting time to reach 5,000+ jobs; zone-based costs considered.
A10: Composite KPI:
A11: Overall Affordability Index=Gross IncomeRent + Council Tax + Travel Cost​
A12: Lower values indicate greater affordability.
... A14: Key Results Summary
A15: % of boroughs affordable for a single male (Room/1-bed) | B15: =COUNTIF('Final Dataset'!Z3:Z34,"<0.3")/COUNT('Final Dataset'!Z3:Z34) -> 0.125
A16: % of boroughs affordable for a single female (Room/1-bed) | B16: =COUNTIF('Final Dataset'!AA3:AA34,"<0.30")/COUNT('Final Dataset'!AA3:AA34) -> 0
A17: % of boroughs affordable for dual-income couple (2-bed) | B17: =COUNTIF('Final Dataset'!AB3:AB34,"<0.30")/COUNT('Final Dataset'!AB3:AB34) -> 0.25
A18: % of boroughs affordable for dual-income family (3-bed) | B18: =COUNTIF('Final Dataset'!AC3:AC34,"<0.3")/COUNT('Final Dataset'!AC3:AC34) -> 0
A19: Median House Price : Salary Ratio | B19: =AVERAGE('Final Dataset'!AF3:AF34) -> 12.385625
A20: Average Commuting Timeto nearest 5000 jobs employment centre (min) | B20: =AVERAGE('Final Dataset'!AE3:AE34) -> 17.351318
A21: Average gender pay gap % | B21: =(SUM('Final Dataset'!C3:C34)-SUM('Final Dataset'!D3:D34))/SUM('Final Dataset'!C3:C34) -> 0.20082536
A22: Median Rent to Income Ratio | B22: =AVERAGE('Final Dataset'!Z:AC) -> 0.41338386
A23: Average Council Tax Burden (as % of pay) | B23: =SUM('Final Dataset'!K3:K34)/(SUM('Final Dataset'!B3:B34)*4*12) -> 0.054954175
A24: Overall Affordability Index to Commute Time Correlation coefficient | B24: =CORREL('Final Dataset'!AG1:AG34,'Final Dataset'!AE1:AE34) -> -0.50033973
A61: Discussion and Conclusion
A62: Women are paid less across all broughs in London, which leads to no boroughs being rent affordable for one bedroom room for any of the the boroughs corresponding median earning female workers.
A63: Only 13% of single median earning male can afford a one bed room.
A64: This is if the 30% housing affordability rule is followed, but reality may be worse due to usage of gross median income instead of income after tax in the calculations.
A65: The original data gross income salary data was collected by ONS and it was a sample size of only 1% of earners data from HMRC, which may skew the results. A larger sample size data would provide far accurate results.
A66: Overall, rent affordability is better for the median dual income household with no kids but according to the 30% rule but in none borough, an average dual income couple could afford a 3-bedroom house.
A67: Median rent to income ratio of 0.41 suggest London as a whole is unaffordable by the 30% rule for the average Londoner. And part time workers and single individuals, especially women, are most strained.
A68: As commute time increases, affordability (your index) tends to improve. Hence, people who move further out from central London get cheaper housing, but they “pay” with longer travel times.
A69: The median house price is around 12 times greater than the median salary, meaning houses are also unaffordable to buy, especially for younger people.
A70: CONCLUSIONS
A71: London’s housing market is structurally unaffordable for most residents. Single renters cannot meet the 30% affordability threshold anywhere, and even dual-income households struggle to secure adequate housing without sacrificing a large share of income.
A72: Gender inequality and the part-time penalty intensify the problem. Council tax and transport costs, which are not tied to income, further disadvantage lower earners.
A73: Policy Implication: Housing affordability in London cannot be solved by income alone; it requires coordinated intervention in rents, taxation, and transport costs.

Sheet Pivot Tables
A1: Average of Single male housing affordability | B1: Average of Single Female housing affordability | C1: Average of Couple Affordability | D1: Average of Family Affordability
A2: 0.38610632 | B2: 0.47977544 | C2: 0.34273264 | D2: 0.44492103
A4: Average of Full-Time Weekly Pay (£) | B4: Average of Part-Time Weekly Pay (£)
A5: 855.7125 | B5: 259.82069
A7: Sum of Female Weekly Pay (£) | B7: Sum of Male Weekly Pay (£)
A8: 21069.6 | B8: 26364.2
A11: Average of Overall Weekly Pay (£)
A12: 733.26875
A18: Borough | B18: Overall Affordability | D18: Borough | E18: Overall Affordability
A20: Kensington and Chelsea | B20: 0.97317847 | D20: Sutton | E20: 0.54223789
A21: Westminster | B21: 0.89656931 | D21: Croydon | E21: 0.55359854
A22: Camden | B22: 0.80471318 | D22: Barnet | E22: 0.55518355
A23: Hackney | B23: 0.78899918 | D23: Havering | E23: 0.55711639
A24: Newham | B24: 0.7641512 | D24: Hillingdon | E24: 0.5817241
A25: Bromley | B25: 0.75176329 | D25: Waltham Forest | E25: 0.60737193
A26: Islington | B26: 0.74659994 | D26: Kingston upon Thames | E26: 0.6093435
A27: Tower Hamlets | B27: 0.72231762 | D27: Richmond upon Thames | E27: 0.61411964
A28: Bexley | B28: 0.72169739 | D28: Greenwich | E28: 0.61617668
A29: Barking and Dagenham | B29: 0.7207113 | D29: Wandsworth | E29: 0.61684157
A30: Ealing | B30: 0.6890193 | D30: Merton | E30: 0.6207063
A31: Hounslow | B31: 0.68762987 | D31: Lewisham | E31: 0.62635605
... A51: Sutton | B51: 0.54223789 | D51: Kensington and Chelsea | E51: 0.97317847

Sheet Final Dataset
A1: Borough | B1: Overall Weekly Pay (£) | C1: Male Weekly Pay (£) | D1: Female Weekly Pay (£) | E1: Part-Time Weekly Pay (£) | F1: Full-Time Weekly Pay (£) | G1: Zone | H1: Band A | I1: Band B | J1: Band C | K1: Band D | L1: Band E | M1: Band F | N1: Band G | O1: Band H | P1: =_xlfn.XLOOKUP(A1,'JTS0501 2022'!BY:BY,'JTS0501 2022'!BZ:BZ) -> 5000EmpPTt | Q1: =_xlfn.XLOOKUP(A1,'JTS0501 2022'!BY:BY,'JTS0501 2022'!CI:CI) -> 5000EmpCyct | R1: =_xlfn.XLOOKUP(A1,'JTS0501 2022'!BY:BY,'JTS0501 2022'!CR:CR) -> 5000EmpCart | S1: =_xlfn.XLOOKUP(A1,'JTS0501 2022'!BY:BY,'JTS0501 2022'!DA:DA) -> 5000EmpWalkt | T1: Four or More Bedrooms | U1: One Bedroom | V1: Room | W1: Studio | X1: Three Bedrooms | Y1: Two Bedrooms | Z1: Single male housing affordability | AA1: Single Female Rent housing affordability | AB1: Couple Rent Affordability | AC1: Family Rent Affordability | AD1: Average rent affordability | AE1: Weighted average Commuting Time | AF1: Median Earning to House Price Ratio | AG1: Overall Affordability | AH1: Annual TfL Fare Price
H2: 811.92667 | I2: 947.24778 | J2: 1082.5689 | K2: 1217.89 | L2: 1488.5322 | M2: 1759.1744 | N2: 2029.8167 | O2: 2435.78 | P2: =_xlfn.XLOOKUP(A2,'JTS0501 2022'!BY:BY,'JTS0501 2022'!BZ:BZ) -> 0 | Q2: =_xlfn.XLOOKUP(A2,'JTS0501 2022'!BY:BY,'JTS0501 2022'!CI:CI) -> 0 | R2: =_xlfn.XLOOKUP(A2,'JTS0501 2022'!BY:BY,'JTS0501 2022'!CR:CR) -> 0 | S2: =_xlfn.XLOOKUP(A2,'JTS0501 2022'!BY:BY,'JTS0501 2022'!DA:DA) -> 0 | T2: 2400 | U2: 1350 | V2: 726 | W2: 0 | X2: 1965 | Y2: 1700
A3: Kensington and Chelsea | B3: 810.1 | C3: 1041.5 | D3: 691.5 | E3: =_xlfn.FORECAST.LINEAR(19,A20:A49,B20:B49) -> 349.71723 | F3: 988 | G3: Zones 1-2 | H3: 1019.9 | I3: 1189.8833 | J3: 1359.8667 | K3: 1529.85 | L3: 1869.8167 | M3: 2209.7833 | N3: 2549.75 | O3: 3059.7 | P3: =_xlfn.XLOOKUP(A3,'JTS0501 2022'!BY:BY,'JTS0501 2022'!BZ:BZ) -> 11.855897 | Q3: =_xlfn.XLOOKUP(A3,'JTS0501 2022'!BY:BY,'JTS0501 2022'!CI:CI) -> 9.2291756 | R3: =_xlfn.XLOOKUP(A3,'JTS0501 2022'!BY:BY,'JTS0501 2022'!CR:CR) -> 9.2115196 | S3: =_xlfn.XLOOKUP(A3,'JTS0501 2022'!BY:BY,'JTS0501 2022'!DA:DA) -> 12.995041 | T3: 8000 | U3: 2396 | V3: 1177 | W3: 1603 | X3: 5688 | Y3: 3358 | Z3: =W3/(C3*4) -> 0.38478157 | AA3: =W3/(D3*4) -> 0.57953724 | AB3: =Y3/((C3+D3)*4) -> 0.48442008 | AC3: =X3/((C3+D3)*4) -> 0.82054241 | AD3: =AVERAGE(Z3:AC3) -> 0.56732032 | AE3: =0.31*P3+0.38*Q3+0.27*R3+0.04*S3 -> 10.189327 | AF3: =_xlfn.XLOOKUP(A3,'House Prices'!C:C,'House Prices'!Z:Z) -> 22.8 | AG3: =(K3+(MEDIAN(T3:Y3)*12)+AH3)/(B3*4*12) -> 0.97317847 | AH3: =_xlfn.XLOOKUP(G3,'TfL Fare'!A4:A47,'TfL Fare'!I4:I47) -> £1,788
A4: Westminster | B4: 843.3 | C4: 932 | D4: 760.2 | E4: 258.1 | F4: 958.2 | G4: Zones 1-2 | H4: 758.34889 | I4: 866.68444 | J4: 975.02 | K4: 1191.6911 | L4: 1408.3622 | M4: 1625.0333 | N4: 1950.04 | P4: =_xlfn.XLOOKUP(A4,'JTS0501 2022'!BY:BY,'JTS0501 2022'!BZ:BZ) -> 9.6599694 | Q4: =_xlfn.XLOOKUP(A4,'JTS0501 2022'!BY:BY,'JTS0501 2022'!CI:CI) -> 8.79643 | R4: =_xlfn.XLOOKUP(A4,'JTS0501 2022'!BY:BY,'JTS0501 2022'!CR:CR) -> 8.0254302 | S4: =_xlfn.XLOOKUP(A4,'JTS0501 2022'!BY:BY,'JTS0501 2022'!DA:DA) -> 11.614199 | T4: 9750 | U4: 2492 | V4: 1000 | W4: 1647 | X4: 4658 | Y4: 3358 | Z4: =W4/(C4*4) -> 0.44179185 | AA4: =W4/(D4*4) -> 0.54163378 | AB4: =Y4/((C4+D4)*4) -> 0.49609975 | AC4: =X4/((C4+D4)*4) -> 0.68815743 | AD4: =AVERAGE(Z4:AC4) -> 0.5419207 | AE4: =0.31*P4+0.38*Q4+0.27*R4+0.04*S4 -> 8.9686681 | AF4: =_xlfn.XLOOKUP(A4,'House Prices'!C:C,'House Prices'!Z:Z) -> 18.31 | AG4: =(K4+MEDIAN(T4:Y4)*12)/(B4*4*12) -> 0.89656931 | AH4: =_xlfn.XLOOKUP(G4,'TfL Fare'!A5:A48,'TfL Fare'!I5:I48) -> £1,788
A5: Camden | B5: 766.6 | C5: 797.5 | D5: 727.6 | E5: =_xlfn.FORECAST.LINEAR(6,A35:A64,B35:B64) -> 289.41935 | F5: 864.8 | G5: Zones 1-3 | H5: 1340.58 | I5: 1564.01 | J5: 1787.44 | K5: 2010.87 | L5: 2457.73 | M5: 2904.59 | N5: 3351.45 | O5: 4021.74 | P5: =_xlfn.XLOOKUP(A5,'JTS0501 2022'!BY:BY,'JTS0501 2022'!BZ:BZ) -> 11.180944 | Q5: =_xlfn.XLOOKUP(A5,'JTS0501 2022'!BY:BY,'JTS0501 2022'!CI:CI) -> 9.4133962 | R5: =_xlfn.XLOOKUP(A5,'JTS0501 2022'!BY:BY,'JTS0501 2022'!CR:CR) -> 8.4902056 | S5: =_xlfn.XLOOKUP(A5,'JTS0501 2022'!BY:BY,'JTS0501 2022'!DA:DA) -> 14.000429 | T5: 0 | U5: 2300 | V5: 0 | W5: 2300 | X5: 4575 | Y5: 3075 | Z5: =W5/(C5*4) -> 0.72100313 | AA5: =W5/(D5*4) -> 0.79026938 | AB5: =Y5/((C5+D5)*4) -> 0.50406531 | AC5: =X5/((C5+D5)*4) -> 0.74995082 | AD5: =AVERAGE(Z5:AC5) -> 0.69132216 | AE5: =0.31*P5+0.38*Q5+0.27*R5+0.04*S5 -> 9.8955559 | AF5: =_xlfn.XLOOKUP(A5,'House Prices'!C:C,'House Prices'!Z:Z) -> 16.84 | AG5: =(K5+MEDIAN(T5:Y5)*12)/(B5*4*12) -> 0.80471318 | AH5: =_xlfn.XLOOKUP(G5,'TfL Fare'!A6:A49,'TfL Fare'!I6:I49) -> 2100
A6: Hackney | B6: 762.5 | C6: 811.4 | D6: 698.4 | E6: 230 | F6: 882 | G6: Zones 1-3 | H6: 1251.58 | I6: 1460.1767 | J6: 1668.7733 | K6: 1877.37 | L6: 2294.5633 | M6: 2711.7567 | N6: 3128.95 | O6: 3754.74 | P6: =_xlfn.XLOOKUP(A6,'JTS0501 2022'!BY:BY,'JTS0501 2022'!BZ:BZ) -> 22.39033 | Q6: =_xlfn.XLOOKUP(A6,'JTS0501 2022'!BY:BY,'JTS0501 2022'!CI:CI) -> 16.689614 | R6: =_xlfn.XLOOKUP(A6,'JTS0501 2022'!BY:BY,'JTS0501 2022'!CR:CR) -> 12.306756 | S6: =_xlfn.XLOOKUP(A6,'JTS0501 2022'!BY:BY,'JTS0501 2022'!DA:DA) -> 37.725421 | T6: 3950 | U6: 2000 | V6: 976 | W6: 1280 | X6: 3200 | Y6: 2500 | Z6: =W6/(C6*4) -> 0.39438008 | AA6: =W6/(D6*4) -> 0.45819015 | AB6: =Y6/((C6+D6)*4) -> 0.41396211 | AC6: =X6/((C6+D6)*4) -> 0.52987151 | AD6: =AVERAGE(Z6:AC6) -> 0.44910096 | AE6: =0.31*P6+0.38*Q6+0.27*R6+0.04*S6 -> 18.114897 | AF6: =_xlfn.XLOOKUP(A6,'House Prices'!C:C,'House Prices'!Z:Z) -> 12.63 | AG6: =(K6+MEDIAN(T6:Y6)*12)/(B6*4*12) -> 0.78899918 | AH6: 2100
A7: Newham | B7: 635.9 | C7: 702.4 | D7: 577.8 | E7: 246.1 | F7: 758.8 | G7: Zones 2-4 | H7: 1149.56 | I7: 1341.1533 | J7: 1532.7467 | K7: 1724.34 | L7: 2107.5267 | M7: 2490.7133 | N7: 2873.9 | O7: 3448.68 | P7: =_xlfn.XLOOKUP(A7,'JTS0501 2022'!BY:BY,'JTS0501 2022'!BZ:BZ) -> 18.702516 | Q7: =_xlfn.XLOOKUP(A7,'JTS0501 2022'!BY:BY,'JTS0501 2022'!CI:CI) -> 12.842758 | R7: =_xlfn.XLOOKUP(A7,'JTS0501 2022'!BY:BY,'JTS0501 2022'!CR:CR) -> 9.710484 | S7: =_xlfn.XLOOKUP(A7,'JTS0501 2022'!BY:BY,'JTS0501 2022'!DA:DA) -> 25.203305 | T7: 2525 | U7: 1650 | V7: 701 | W7: 1380 | X7: 2200 | Y7: 1950 | Z7: =W7/(C7*4) -> 0.49117312 | AA7: =W7/(D7*4) -> 0.59709242 | AB7: =Y7/((C7+D7)*4) -> 0.38079988 | AC7: =X7/((C7+D7)*4) -> 0.42962037 | AD7: =AVERAGE(Z7:AC7) -> 0.47467145 | AE7: =0.31*P7+0.38*Q7+0.27*R7+0.04*S7 -> 14.307991 | AF7: =_xlfn.XLOOKUP(A7,'House Prices'!C:C,'House Prices'!Z:Z) -> 11.21 | AG7: =(K7+MEDIAN(T7:Y7)*12)/(B7*4*12) -> 0.7641512 | AH7: 1484
A8: Bromley | B8: 818.9 | C8: 943.1 | D8: 704.7 | E8: 252.1 | F8: 958.2 | G8: Zones 3-6 | H8: 1299.8067 | I8: 1516.4411 | J8: 1733.0756 | K8: 1949.71 | L8: 2382.9789 | M8: 2816.2478 | N8: 3249.5167 | O8: 3899.42 | P8: =_xlfn.XLOOKUP(A8,'JTS0501 2022'!BY:BY,'JTS0501 2022'!BZ:BZ) -> 23.29931 | Q8: =_xlfn.XLOOKUP(A8,'JTS0501 2022'!BY:BY,'JTS0501 2022'!CI:CI) -> 18.558242 | R8: =_xlfn.XLOOKUP(A8,'JTS0501 2022'!BY:BY,'JTS0501 2022'!CR:CR) -> 12.993894 | S8: =_xlfn.XLOOKUP(A8,'JTS0501 2022'!BY:BY,'JTS0501 2022'!DA:DA) -> 42.817868 | T8: 4090 | U8: 2000 | V8: 875 | W8: 1450 | X8: 3500 | Y8: 2600 | Z8: =W8/(C8*4) -> 0.38437069 | AA8: =W8/(D8*4) -> 0.51440329 | AB8: =Y8/((C8+D8)*4) -> 0.39446535 | AC8: =X8/((C8+D8)*4) -> 0.53101105 | AD8: =AVERAGE(Z8:AC8) -> 0.45606259 | AE8: =0.31*P8+0.38*Q8+0.27*R8+0.04*S8 -> 19.495984 | AF8: =_xlfn.XLOOKUP(A8,'House Prices'!C:C,'House Prices'!Z:Z) -> 10.56 | AG8: =(K8+MEDIAN(T8:Y8)*12)/(B8*4*12) -> 0.75176329 | AH8: 1780
A9: Islington | B9: 811.2 | C9: 872.7 | D9: 748.5 | E9: 276.6 | F9: 935 | G9: Zones 1-3 | H9: 1280.54 | I9: 1493.9633 | J9: 1707.3867 | K9: 1920.81 | L9: 2347.6567 | M9: 2774.5033 | N9: 3201.35 | O9: 3841.62 | P9: =_xlfn.XLOOKUP(A9,'JTS0501 2022'!BY:BY,'JTS0501 2022'!BZ:BZ) -> 15.348288 | Q9: =_xlfn.XLOOKUP(A9,'JTS0501 2022'!BY:BY,'JTS0501 2022'!CI:CI) -> 11.537751 | R9: =_xlfn.XLOOKUP(A9,'JTS0501 2022'!BY:BY,'JTS0501 2022'!CR:CR) -> 9.2823739 | S9: =_xlfn.XLOOKUP(A9,'JTS0501 2022'!BY:BY,'JTS0501 2022'!DA:DA) -> 20.954541 | T9: 4500 | U9: 2000 | V9: 895 | W9: 1400 | X9: 3100 | Y9: 2525 | Z9: =W9/(C9*4) -> 0.4010542 | AA9: =W9/(D9*4) -> 0.46760187 | AB9: =Y9/((C9+D9)*4) -> 0.38937207 | AC9: =X9/((C9+D9)*4) -> 0.47804096 | AD9: =AVERAGE(Z9:AC9) -> 0.43401727 | AE9: =0.31*P9+0.38*Q9+0.27*R9+0.04*S9 -> 12.486738 | AF9: =_xlfn.XLOOKUP(A9,'House Prices'!C:C,'House Prices'!Z:Z) -> 13.22 | AG9: =(K9+MEDIAN(T9:Y9)*12)/(B9*4*12) -> 0.74659994 | AH9: 2100
A10: Tower Hamlets | B10: 766.5 | C10: 806.4 | D10: 691.8 | E10: 240.9 | F10: 882.2 | G10: Zones 1-2 | H10: 1117.0067 | I10: 1303.1744 | J10: 1489.3422 | K10: 1675.51 | L10: 2047.8456 | M10: 2420.1811 | N10: 2792.5167 | O10: 3351.02 | P10: =_xlfn.XLOOKUP(A10,'JTS0501 2022'!BY:BY,'JTS0501 2022'!BZ:BZ) -> 11.385768 | Q10: =_xlfn.XLOOKUP(A10,'JTS0501 2022'!BY:BY,'JTS0501 2022'!CI:CI) -> 9.1361891 | R10: =_xlfn.XLOOKUP(A10,'JTS0501 2022'!BY:BY,'JTS0501 2022'!CR:CR) -> 8.0554667 | S10: =_xlfn.XLOOKUP(A10,'JTS0501 2022'!BY:BY,'JTS0501 2022'!DA:DA) -> 12.60087 | T10: 3700 | U10: 1850 | V10: 852 | W10: 1750 | X10: 2750 | Y10: 2300 | Z10: =W10/(C10*4) -> 0.54253472 | AA10: =W10/(D10*4) -> 0.63240821 | AB10: =Y10/((C10+D10)*4) -> 0.38379389 | AC10: =X10/((C10+D10)*4) -> 0.45888399 | AD10: =AVERAGE(Z10:AC10) -> 0.5044052 | AE10: =0.31*P10+0.38*Q10+0.27*R10+0.04*S10 -> 9.6803507 | AF10: =_xlfn.XLOOKUP(A10,'House Prices'!C:C,'House Prices'!Z:Z) -> 10.21 | AG10: =(K10+MEDIAN(T10:Y10)*12)/(B10*4*12) -> 0.72231762 | AH10: 1788
A11: Bexley | B11: 694.4 | C11: 861 | D11: 599.2 | E11: 240.7 | F11: 849.1 | G11: Zones 4-6 | H11: 1436.6933 | I11: 1676.1422 | J11: 1915.5911 | K11: 2155.04 | L11: 2633.9378 | M11: 3112.8356 | N11: 3591.7333 | O11: 4310.08 | P11: =_xlfn.XLOOKUP(A11,'JTS0501 2022'!BY:BY,'JTS0501 2022'!BZ:BZ) -> 37.547368 | Q11: =_xlfn.XLOOKUP(A11,'JTS0501 2022'!BY:BY,'JTS0501 2022'!CI:CI) -> 27.115534 | R11: =_xlfn.XLOOKUP(A11,'JTS0501 2022'!BY:BY,'JTS0501 2022'!CR:CR) -> 16.474677 | S11: =_xlfn.XLOOKUP(A11,'JTS0501 2022'!BY:BY,'JTS0501 2022'!DA:DA) -> 69.900254 | T11: 3200 | U11: 1650 | V11: 776 | W11: 1160 | X11: 2400 | Y11: 2000 | Z11: =W11/(C11*4) -> 0.33681765 | AA11: =W11/(D11*4) -> 0.48397864 | AB11: =Y11/((C11+D11)*4) -> 0.34241885 | AC11: =X11/((C11+D11)*4) -> 0.41090262 | AD11: =AVERAGE(Z11:AC11) -> 0.39352944 | AE11: =0.31*P11+0.38*Q11+0.27*R11+0.04*S11 -> 29.18776 | AF11: =_xlfn.XLOOKUP(A11,'House Prices'!C:C,'House Prices'!Z:Z) -> 9.41 | AG11: =(K11+MEDIAN(T11:Y11)*12)/(B11*4*12) -> 0.72169739 | AH11: 1484
A12: Barking and Dagenham | B12: 612.9 | C12: 659.1 | D12: 571.7 | E12: 266.4 | F12: 744.1 | G12: Zones 4-5 | H12: 1335.1667 | I12: 1557.6944 | J12: 1780.2222 | K12: 2002.75 | L12: 2447.8056 | M12: 2892.8611 | N12: 3337.9167 | O12: 4005.5 | P12: =_xlfn.XLOOKUP(A12,'JTS0501 2022'!BY:BY,'JTS0501 2022'!BZ:BZ) -> 23.884422 | Q12: =_xlfn.XLOOKUP(A12,'JTS0501 2022'!BY:BY,'JTS0501 2022'!CI:CI) -> 16.684623 | R12: =_xlfn.XLOOKUP(A12,'JTS0501 2022'!BY:BY,'JTS0501 2022'!CR:CR) -> 12.454585 | S12: =_xlfn.XLOOKUP(A12,'JTS0501 2022'!BY:BY,'JTS0501 2022'!DA:DA) -> 36.508477 | T12: 3150 | U12: 1450 | V12: 726 | W12: 1100 | X12: 2400 | Y12: 1750 | Z12: =W12/(C12*4) -> 0.41723562 | AA12: =W12/(D12*4) -> 0.48102151 | AB12: =Y12/((C12+D12)*4) -> 0.35545986 | AC12: =X12/((C12+D12)*4) -> 0.48748781 | AD12: =AVERAGE(Z12:AC12) -> 0.4353012 | AE12: =0.31*P12+0.38*Q12+0.27*R12+0.04*S12 -> 18.567405 | AF12: =_xlfn.XLOOKUP(A12,'House Prices'!C:C,'House Prices'!Z:Z) -> 9.52 | AG12: =(K12+MEDIAN(T12:Y12)*12)/(B12*4*12) -> 0.7207113 | AH12: 1340
A13: Ealing | B13: 684.8 | C13: 737.7 | D13: 651.2 | E13: 243.3 | F13: 784.9 | G13: Zones 2-5 | H13: 1298.8933 | I13: 1515.3756 | J13: 1731.8578 | K13: 1948.34 | L13: 2381.3044 | M13: 2814.2689 | N13: 3247.2333 | O13: 3896.68 | P13: =_xlfn.XLOOKUP(A13,'JTS0501 2022'!BY:BY,'JTS0501 2022'!BZ:BZ) -> 27.25713 | Q13: =_xlfn.XLOOKUP(A13,'JTS0501 2022'!BY:BY,'JTS0501 2022'!CI:CI) -> 18.617865 | R13: =_xlfn.XLOOKUP(A13,'JTS0501 2022'!BY:BY,'JTS0501 2022'!CR:CR) -> 13.577007 | S13: =_xlfn.XLOOKUP(A13,'JTS0501 2022'!BY:BY,'JTS0501 2022'!DA:DA) -> 42.454195 | T13: 2900 | U13: 1550 | V13: 826 | W13: 1345 | X13: 2445 | Y13: 1900 | Z13: =W13/(C13*4) -> 0.45580859 | AA13: =W13/(D13*4) -> 0.51635442 | AB13: =Y13/((C13+D13)*4) -> 0.34199726 | AC13: =X13/((C13+D13)*4) -> 0.44009648 | AD13: =AVERAGE(Z13:AC13) -> 0.43856419 | AE13: =0.31*P13+0.38*Q13+0.27*R13+0.04*S13 -> 20.888459 | AF13: =_xlfn.XLOOKUP(A13,'House Prices'!C:C,'House Prices'!Z:Z) -> 12.81 | AG13: =(K13+MEDIAN(T13:Y13)*12)/(B13*4*12) -> 0.6890193 | AH13: =_xlfn.XLOOKUP(G13,'TfL Fare'!A13:A56,'TfL Fare'!I13:I56) -> £1,780
A14: Hounslow | B14: 659.3 | C14: 738.5 | D14: 574.9 | E14: 239.7 | F14: 766.6 | G14: Zones 2-6 | H14: 1327.34 | I14: 1548.5633 | J14: 1769.7867 | K14: 1991.01 | L14: 2433.4567 | M14: 2875.9033 | N14: 3318.35 | O14: 3982.02 | P14: =_xlfn.XLOOKUP(A14,'JTS0501 2022'!BY:BY,'JTS0501 2022'!BZ:BZ) -> 19.163132 | Q14: =_xlfn.XLOOKUP(A14,'JTS0501 2022'!BY:BY,'JTS0501 2022'!CI:CI) -> 12.882431 | R14: =_xlfn.XLOOKUP(A14,'JTS0501 2022'!BY:BY,'JTS0501 2022'!CR:CR) -> 10.454078 | S14: =_xlfn.XLOOKUP(A14,'JTS0501 2022'!BY:BY,'JTS0501 2022'!DA:DA) -> 24.023985 | T14: 3100 | U14: 1495 | V14: 700 | W14: 1150 | X14: 2250 | Y14: 1800 | Z14: =W14/(C14*4) -> 0.38930264 | AA14: =W14/(D14*4) -> 0.50008697 | AB14: =Y14/((C14+D14)*4) -> 0.3426222 | AC14: =X14/((C14+D14)*4) -> 0.42827775 | AD14: =AVERAGE(Z14:AC14) -> 0.41507239 | AE14: =0.31*P14+0.38*Q14+0.27*R14+0.04*S14 -> 14.619455 | AF14: =_xlfn.XLOOKUP(A14,'House Prices'!C:C,'House Prices'!Z:Z) -> 12.02 | AG14: =(K14+MEDIAN(T14:Y14)*12)/(B14*4*12) -> 0.68762987 | AH14: 2236
A15: Haringey | B15: 727.8 | C15: 745.6 | D15: 683.1 | E15: 240.5 | F15: 814.5 | G15: Zones 3-4 | H15: 1404.88 | I15: 1639.0267 | J15: 1873.1733 | K15: 2107.32 | L15: 2575.6133 | M15: 3043.9067 | N15: 3512.2 | O15: 4214.64 | P15: =_xlfn.XLOOKUP(A15,'JTS0501 2022'!BY:BY,'JTS0501 2022'!BZ:BZ) -> 27.571533 | Q15: =_xlfn.XLOOKUP(A15,'JTS0501 2022'!BY:BY,'JTS0501 2022'!CI:CI) -> 18.96057 | R15: =_xlfn.XLOOKUP(A15,'JTS0501 2022'!BY:BY,'JTS0501 2022'!CR:CR) -> 13.424043 | S15: =_xlfn.XLOOKUP(A15,'JTS0501 2022'!BY:BY,'JTS0501 2022'!DA:DA) -> 45.407653 | T15: 3350 | U15: 1625 | V15: 686 | W15: 1067 | X15: 2500 | Y15: 1993 | Z15: =W15/(C15*4) -> 0.35776556 | AA15: =W15/(D15*4) -> 0.39049919 | AB15: =Y15/((C15+D15)*4) -> 0.34874361 | AC15: =X15/((C15+D15)*4) -> 0.43746063 | AD15: =AVERAGE(Z15:AC15) -> 0.38361725 | AE15: =0.31*P15+0.38*Q15+0.27*R15+0.04*S15 -> 21.19299 | AF15: =_xlfn.XLOOKUP(A15,'House Prices'!C:C,'House Prices'!Z:Z) -> 12.64 | AG15: =(K15+MEDIAN(T15:Y15)*12)/(B15*4*12) -> 0.68171544 | AH15: =_xlfn.XLOOKUP(G15,'TfL Fare'!A15:A58,'TfL Fare'!I15:I58) -> £1,340
A16: Hammersmith and Fulham | B16: 798.5 | C16: 889.5 | D16: 702.3 | E16: 262.2 | F16: 862.4 | G16: Zone 2 only | H16: 924.51333 | I16: 1078.5989 | J16: 1232.6844 | K16: 1386.77 | L16: 1694.9411 | M16: 2003.1122 | N16: 2311.2833 | O16: 2773.54 | P16: =_xlfn.XLOOKUP(A16,'JTS0501 2022'!BY:BY,'JTS0501 2022'!BZ:BZ) -> 13.558101 | Q16: =_xlfn.XLOOKUP(A16,'JTS0501 2022'!BY:BY,'JTS0501 2022'!CI:CI) -> 9.7013344 | R16: =_xlfn.XLOOKUP(A16,'JTS0501 2022'!BY:BY,'JTS0501 2022'!CR:CR) -> 8.5055886 | S16: =_xlfn.XLOOKUP(A16,'JTS0501 2022'!BY:BY,'JTS0501 2022'!DA:DA) -> 14.771245 | T16: 4600 | U16: 1850 | V16: 1026 | W16: 1500 | X16: 3300 | Y16: 2250 | Z16: =W16/(C16*4) -> 0.42158516 | AA16: =W16/(D16*4) -> 0.53395985 | AB16: =Y16/((C16+D16)*4) -> 0.35337354 | AC16: =X16/((C16+D16)*4) -> 0.51828119 | AD16: =AVERAGE(Z16:AC16) -> 0.45679993 | AE16: =0.31*P16+0.38*Q16+0.27*R16+0.04*S16 -> 10.776877 | AF16: =_xlfn.XLOOKUP(A16,'House Prices'!C:C,'House Prices'!Z:Z) -> 15.83 | AG16: =(K16+MEDIAN(T16:Y16)*12)/(B16*4*12) -> 0.67801007 | AH16: =_xlfn.XLOOKUP(G16,'TfL Fare'!A7:A50,'TfL Fare'!I7:I50) -> 1340
A17: Lambeth | B17: 797.4 | C17: 854.9 | D17: 747.4 | E17: 288.5 | F17: 883.5 | G17: Zones 1-3 | H17: 1243.6067 | I17: 1450.8744 | J17: 1658.1422 | K17: 1865.41 | L17: 2279.9456 | M17: 2694.4811 | N17: 3109.0167 | O17: 3730.82 | P17: =_xlfn.XLOOKUP(A17,'JTS0501 2022'!BY:BY,'JTS0501 2022'!BZ:BZ) -> 21.620164 | Q17: =_xlfn.XLOOKUP(A17,'JTS0501 2022'!BY:BY,'JTS0501 2022'!CI:CI) -> 15.166524 | R17: =_xlfn.XLOOKUP(A17,'JTS0501 2022'!BY:BY,'JTS0501 2022'!CR:CR) -> 12.02157 | S17: =_xlfn.XLOOKUP(A17,'JTS0501 2022'!BY:BY,'JTS0501 2022'!DA:DA) -> 32.843477 | T17: 3750 | U17: 1800 | V17: 830 | W17: 1375 | X17: 2850 | Y17: 2205 | Z17: =W17/(C17*4) -> 0.40209381 | AA17: =W17/(D17*4) -> 0.45992775 | AB17: =Y17/((C17+D17)*4) -> 0.3440367 | AC17: =X17/((C17+D17)*4) -> 0.44467328 | AD17: =AVERAGE(Z17:AC17) -> 0.41268289 | AE17: =0.31*P17+0.38*Q17+0.27*R17+0.04*S17 -> 17.025093 | AF17: =_xlfn.XLOOKUP(A17,'House Prices'!C:C,'House Prices'!Z:Z) -> 11.12 | AG17: =(K17+MEDIAN(T17:Y17)*12)/(B17*4*12) -> 0.67655845 | AH17: 2100
A18: Southwark | B18: 788.6 | C18: 833.2 | D18: 713.3 | E18: 239.1 | F18: 880.4 | G18: Zones 1-3 | H18: 1195.32 | I18: 1394.54 | J18: 1593.76 | K18: 1792.98 | L18: 2191.42 | M18: 2589.86 | N18: 2988.3 | O18: 3585.96 | P18: =_xlfn.XLOOKUP(A18,'JTS0501 2022'!BY:BY,'JTS0501 2022'!BZ:BZ) -> 16.408721 | Q18: =_xlfn.XLOOKUP(A18,'JTS0501 2022'!BY:BY,'JTS0501 2022'!CI:CI) -> 11.778046 | R18: =_xlfn.XLOOKUP(A18,'JTS0501 2022'!BY:BY,'JTS0501 2022'!CR:CR) -> 10.280972 | S18: =_xlfn.XLOOKUP(A18,'JTS0501 2022'!BY:BY,'JTS0501 2022'!DA:DA) -> 21.410665 | T18: 3500 | U18: 1725 | V18: 875 | W18: 1400 | X18: 2700 | Y18: 2200 | Z18: =W18/(C18*4) -> 0.42006721 | AA18: =W18/(D18*4) -> 0.49067713 | AB18: =Y18/((C18+D18)*4) -> 0.35564177 | AC18: =X18/((C18+D18)*4) -> 0.43646945 | AD18: =AVERAGE(Z18:AC18) -> 0.42571389 | AE18: =0.31*P18+0.38*Q18+0.27*R18+0.04*S18 -> 13.19465 | AF18: =_xlfn.XLOOKUP(A18,'House Prices'!C:C,'House Prices'!Z:Z) -> 12.24 | AG18: =(K18+MEDIAN(T18:Y18)*12)/(B18*4*12) -> 0.66951401 | AH18: 2100
A19: Harrow | B19: 669.2 | C19: 814.7 | D19: 584.4 | E19: 255.6 | F19: 853.8 | G19: Zones 5-6 | H19: 1524.2133 | I19: 1778.2489 | J19: 2032.2844 | K19: 2286.32 | L19: 2794.3911 | M19: 3302.4622 | N19: 3810.5333 | O19: 4572.64 | P19: =_xlfn.XLOOKUP(A19,'JTS0501 2022'!BY:BY,'JTS0501 2022'!BZ:BZ) -> 23.258123 | Q19: =_xlfn.XLOOKUP(A19,'JTS0501 2022'!BY:BY,'JTS0501 2022'!CI:CI) -> 17.241083 | R19: =_xlfn.XLOOKUP(A19,'JTS0501 2022'!BY:BY,'JTS0501 2022'!CR:CR) -> 13.063193 | S19: =_xlfn.XLOOKUP(A19,'JTS0501 2022'!BY:BY,'JTS0501 2022'!DA:DA) -> 39.482942 | T19: 2800 | U19: 1400 | V19: 826 | W19: 1088 | X19: 2150 | Y19: 1700 | Z19: =W19/(C19*4) -> 0.33386523 | AA19: =W19/(D19*4) -> 0.46543463 | AB19: =Y19/((C19+D19)*4) -> 0.30376671 | AC19: =X19/((C19+D19)*4) -> 0.38417554 | AD19: =AVERAGE(Z19:AC19) -> 0.37181053 | AE19: =0.31*P19+0.38*Q19+0.27*R19+0.04*S19 -> 18.86801 | AF19: =_xlfn.XLOOKUP(A19,'House Prices'!C:C,'House Prices'!Z:Z) -> 12.85 | AG19: =(K19+MEDIAN(T19:Y19)*12)/(B19*4*12) -> 0.65022664 | AH19: =_xlfn.XLOOKUP(G19,'TfL Fare'!A12:A55,'TfL Fare'!I12:I55) -> £1,340
A20: Enfield | B20: 646.2 | C20: 715.9 | D20: 603.7 | E20: 251 | F20: 838.4 | G20: Zones 4-6 | H20: 1376.9867 | I20: 1606.4844 | J20: 1835.9822 | K20: 2065.48 | L20: 2524.4756 | M20: 2983.4711 | N20: 3442.4667 | O20: 4130.96 | P20: =_xlfn.XLOOKUP(A20,'JTS0501 2022'!BY:BY,'JTS0501 2022'!BZ:BZ) -> 26.530366 | Q20: =_xlfn.XLOOKUP(A20,'JTS0501 2022'!BY:BY,'JTS0501 2022'!CI:CI) -> 17.631755 | R20: =_xlfn.XLOOKUP(A20,'JTS0501 2022'!BY:BY,'JTS0501 2022'!CR:CR) -> 12.472848 | S20: =_xlfn.XLOOKUP(A20,'JTS0501 2022'!BY:BY,'JTS0501 2022'!DA:DA) -> 40.053618 | T20: 2900 | U20: 1350 | V20: 738 | W20: 1100 | X20: 2050 | Y20: 1650 | Z20: =W20/(C20*4) -> 0.38413186 | AA20: =W20/(D20*4) -> 0.45552427 | AB20: =Y20/((C20+D20)*4) -> 0.31259473 | AC20: =X20/((C20+D20)*4) -> 0.38837527 | AD20: =AVERAGE(Z20:AC20) -> 0.38515653 | AE20: =0.31*P20+0.38*Q20+0.27*R20+0.04*S20 -> 19.894294 | AF20: =_xlfn.XLOOKUP(A20,'House Prices'!C:C,'House Prices'!Z:Z) -> 10.59 | AG20: =(K20+MEDIAN(T20:Y20)*12)/(B20*4*12) -> 0.64690627 | AH20: =_xlfn.XLOOKUP(G20,'TfL Fare'!A26:A69,'TfL Fare'!I26:I69) -> 1484
A21: Redbridge | B21: 669 | C21: 804.9 | D21: 552 | E21: 240.2 | F21: 820.1 | G21: Zone 4 only | H21: 1393.2467 | I21: 1625.4544 | J21: 1857.6622 | K21: 2089.87 | L21: 2554.2856 | M21: 3018.7011 | N21: 3483.1167 | O21: 4179.74 | P21: =_xlfn.XLOOKUP(A21,'JTS0501 2022'!BY:BY,'JTS0501 2022'!BZ:BZ) -> 25.097612 | Q21: =_xlfn.XLOOKUP(A21,'JTS0501 2022'!BY:BY,'JTS0501 2022'!CI:CI) -> 17.587397 | R21: =_xlfn.XLOOKUP(A21,'JTS0501 2022'!BY:BY,'JTS0501 2022'!CR:CR) -> 13.428494 | S21: =_xlfn.XLOOKUP(A21,'JTS0501 2022'!BY:BY,'JTS0501 2022'!DA:DA) -> 40.419916 | T21: 2600 | U21: 1375 | V21: 876 | W21: 998 | X21: 2100 | Y21: 1700 | Z21: =W21/(C21*4) -> 0.30997639 | AA21: =W21/(D21*4) -> 0.45199275 | AB21: =Y21/((C21+D21)*4) -> 0.31321394 | AC21: =X21/((C21+D21)*4) -> 0.38691134 | AD21: =AVERAGE(Z21:AC21) -> 0.36552361 | AE21: =0.31*P21+0.38*Q21+0.27*R21+0.04*S21 -> 19.70596 | AF21: =_xlfn.XLOOKUP(A21,'House Prices'!C:C,'House Prices'!Z:Z) -> 11.56 | AG21: =(K21+MEDIAN(T21:Y21)*12)/(B21*4*12) -> 0.63963222 | AH21: =_xlfn.XLOOKUP(G21,'TfL Fare'!A22:A65,'TfL Fare'!I22:I65) -> £1,340
A22: Brent | B22: 646.2 | C22: 720.7 | D22: 581.8 | E22: 289.5 | F22: 747.6 | G22: Zones 3-4 | H22: 1357.3667 | I22: 1583.5944 | J22: 1809.8222 | K22: 2036.05 | L22: 2488.5056 | M22: 2940.9611 | N22: 3393.4167 | O22: 4072.1 | P22: =_xlfn.XLOOKUP(A22,'JTS0501 2022'!BY:BY,'JTS0501 2022'!BZ:BZ) -> 20.408482 | Q22: =_xlfn.XLOOKUP(A22,'JTS0501 2022'!BY:BY,'JTS0501 2022'!CI:CI) -> 14.596499 | R22: =_xlfn.XLOOKUP(A22,'JTS0501 2022'!BY:BY,'JTS0501 2022'!CR:CR) -> 11.609253 | S22: =_xlfn.XLOOKUP(A22,'JTS0501 2022'!BY:BY,'JTS0501 2022'!DA:DA) -> 30.404375 | T22: 2500 | U22: 1300 | V22: 718 | W22: 995 | X22: 2000 | Y22: 1600 | Z22: =W22/(C22*4) -> 0.34515055 | AA22: =W22/(D22*4) -> 0.42755242 | AB22: =Y22/((C22+D22)*4) -> 0.30710173 | AC22: =X22/((C22+D22)*4) -> 0.38387716 | AD22: =AVERAGE(Z22:AC22) -> 0.36592046 | AE22: =0.31*P22+0.38*Q22+0.27*R22+0.04*S22 -> 16.223972 | AF22: =_xlfn.XLOOKUP(A22,'House Prices'!C:C,'House Prices'!Z:Z) -> 14.18 | AG22: =(K22+MEDIAN(T22:Y22)*12)/(B22*4*12) -> 0.6266136 | AH22: =_xlfn.XLOOKUP(G22,'TfL Fare'!A8:A51,'TfL Fare'!I8:I51) -> £1,340
A23: Lewisham | B23: 706.4 | C23: 739 | D23: 675.2 | E23: 248.8 | F23: 843 | G23: Zones 2-4 | H23: 1358.6533 | I23: 1585.0956 | J23: 1811.5378 | K23: 2037.98 | L23: 2490.8644 | M23: 2943.7489 | N23: 3396.6333 | O23: 4075.96 | P23: =_xlfn.XLOOKUP(A23,'JTS0501 2022'!BY:BY,'JTS0501 2022'!BZ:BZ) -> 28.334676 | Q23: =_xlfn.XLOOKUP(A23,'JTS0501 2022'!BY:BY,'JTS0501 2022'!CI:CI) -> 21.584846 | R23: =_xlfn.XLOOKUP(A23,'JTS0501 2022'!BY:BY,'JTS0501 2022'!CR:CR) -> 16.2336 | S23: =_xlfn.XLOOKUP(A23,'JTS0501 2022'!BY:BY,'JTS0501 2022'!DA:DA) -> 53.56448 | T23: 2900 | U23: 1450 | V23: 821 | W23: 1150 | X23: 2200 | Y23: 1750 | Z23: =W23/(C23*4) -> 0.38903924 | AA23: =W23/(D23*4) -> 0.42579976 | AB23: =Y23/((C23+D23)*4) -> 0.30936218 | AC23: =X23/((C23+D23)*4) -> 0.38891246 | AD23: =AVERAGE(Z23:AC23) -> 0.37827841 | AE23: =0.31*P23+0.38*Q23+0.27*R23+0.04*S23 -> 23.511642 | AF23: =_xlfn.XLOOKUP(A23,'House Prices'!C:C,'House Prices'!Z:Z) -> 10.14 | AG23: =(K23+MEDIAN(T23:Y23)*12)/(B23*4*12) -> 0.62635605 | AH23: 1484
A24: Merton | B24: 721.6 | C24: 844.7 | D24: 670.9 | E24: 256.1 | F24: 876.3 | G24: Zones 3-4 | H24: 1332.8533 | I24: 1554.9956 | J24: 1777.1378 | K24: 1999.28 | L24: 2443.5644 | M24: 2887.8489 | N24: 3332.1333 | O24: 3998.56 | P24: =_xlfn.XLOOKUP(A24,'JTS0501 2022'!BY:BY,'JTS0501 2022'!BZ:BZ) -> 20.882229 | Q24: =_xlfn.XLOOKUP(A24,'JTS0501 2022'!BY:BY,'JTS0501 2022'!CI:CI) -> 13.546968 | R24: =_xlfn.XLOOKUP(A24,'JTS0501 2022'!BY:BY,'JTS0501 2022'!CR:CR) -> 10.661471 | S24: =_xlfn.XLOOKUP(A24,'JTS0501 2022'!BY:BY,'JTS0501 2022'!DA:DA) -> 26.465968 | T24: 3350 | U24: 1500 | V24: 824 | W24: 1388 | X24: 2450 | Y24: 1750 | Z24: =W24/(C24*4) -> 0.41079673 | AA24: =W24/(D24*4) -> 0.51721568 | AB24: =Y24/((C24+D24)*4) -> 0.28866456 | AC24: =X24/((C24+D24)*4) -> 0.40413038 | AD24: =AVERAGE(Z24:AC24) -> 0.40520184 | AE24: =0.31*P24+0.38*Q24+0.27*R24+0.04*S24 -> 15.558575 | AF24: =_xlfn.XLOOKUP(A24,'House Prices'!C:C,'House Prices'!Z:Z) -> 11.74 | AG24: =(K24+MEDIAN(T24:Y24)*12)/(B24*4*12) -> 0.6207063 | AH24: =_xlfn.XLOOKUP(G24,'TfL Fare'!A20:A63,'TfL Fare'!I20:I63) -> £1,340
A25: Wandsworth | B25: 843.3 | C25: 912.3 | D25: 796.4 | E25: 251.3 | F25: 921.1 | G25: Zones 1-3 | H25: 645.84 | I25: 753.48 | J25: 861.12 | K25: 968.76 | L25: 1184.04 | M25: 1399.32 | N25: 1614.6 | O25: 1937.52 | P25: =_xlfn.XLOOKUP(A25,'JTS0501 2022'!BY:BY,'JTS0501 2022'!BZ:BZ) -> 23.317936 | Q25: =_xlfn.XLOOKUP(A25,'JTS0501 2022'!BY:BY,'JTS0501 2022'!CI:CI) -> 16.64153 | R25: =_xlfn.XLOOKUP(A25,'JTS0501 2022'!BY:BY,'JTS0501 2022'!CR:CR) -> 13.791132 | S25: =_xlfn.XLOOKUP(A25,'JTS0501 2022'!BY:BY,'JTS0501 2022'!DA:DA) -> 36.662914 | T25: 4125 | U25: 1750 | V25: 1139 | W25: 1350 | X25: 2900 | Y25: 2250 | Z25: =W25/(C25*4) -> 0.3699441 | AA25: =W25/(D25*4) -> 0.42378202 | AB25: =Y25/((C25+D25)*4) -> 0.32919764 | AC25: =X25/((C25+D25)*4) -> 0.42429917 | AD25: =AVERAGE(Z25:AC25) -> 0.38680573 | AE25: =0.31*P25+0.38*Q25+0.27*R25+0.04*S25 -> 18.742464 | AF25: =_xlfn.XLOOKUP(A25,'House Prices'!C:C,'House Prices'!Z:Z) -> 12.87 | AG25: =(K25+MEDIAN(T25:Y25)*12)/(B25*4*12) -> 0.61684157 | AH25: =2100 -> 2100
A26: Greenwich | B26: 749.6 | C26: 843.2 | D26: 656.5 | E26: 280.6 | F26: 852.1 | G26: Zones 2-4 | H26: 1280.3533 | I26: 1493.7456 | J26: 1707.1378 | K26: 1920.53 | L26: 2347.3144 | M26: 2774.0989 | N26: 3200.8833 | O26: 3841.06 | P26: =_xlfn.XLOOKUP(A26,'JTS0501 2022'!BY:BY,'JTS0501 2022'!BZ:BZ) -> 24.682605 | Q26: =_xlfn.XLOOKUP(A26,'JTS0501 2022'!BY:BY,'JTS0501 2022'!CI:CI) -> 16.480559 | R26: =_xlfn.XLOOKUP(A26,'JTS0501 2022'!BY:BY,'JTS0501 2022'!CR:CR) -> 11.955903 | S26: =_xlfn.XLOOKUP(A26,'JTS0501 2022'!BY:BY,'JTS0501 2022'!DA:DA) -> 35.085299 | T26: 2750 | U26: 1525 | V26: 770 | W26: 1150 | X26: 2100 | Y26: 1850 | Z26: =W26/(C26*4) -> 0.340963 | AA26: =W26/(D26*4) -> 0.43792841 | AB26: =Y26/((C26+D26)*4) -> 0.30839501 | AC26: =X26/((C26+D26)*4) -> 0.35007001 | AD26: =AVERAGE(Z26:AC26) -> 0.35933911 | AE26: =0.31*P26+0.38*Q26+0.27*R26+0.04*S26 -> 18.545726 | AF26: =_xlfn.XLOOKUP(A26,'House Prices'!C:C,'House Prices'!Z:Z) -> 10.09 | AG26: =(K26+MEDIAN(T26:Y26)*12)/(B26*4*12) -> 0.61617668 | AH26: 1484
A27: Richmond upon Thames | B27: 824 | C27: 1022.5 | D27: 733.9 | E27: 241.4 | F27: 962 | G27: Zones 3-6 | H27: 1509.1067 | I27: 1760.6244 | J27: 2012.1422 | K27: 2263.66 | L27: 2766.6956 | M27: 3269.7311 | N27: 3772.7667 | O27: 4527.32 | P27: =_xlfn.XLOOKUP(A27,'JTS0501 2022'!BY:BY,'JTS0501 2022'!BZ:BZ) -> 22.076278 | Q27: =_xlfn.XLOOKUP(A27,'JTS0501 2022'!BY:BY,'JTS0501 2022'!CI:CI) -> 16.387142 | R27: =_xlfn.XLOOKUP(A27,'JTS0501 2022'!BY:BY,'JTS0501 2022'!CR:CR) -> 13.058855 | S27: =_xlfn.XLOOKUP(A27,'JTS0501 2022'!BY:BY,'JTS0501 2022'!DA:DA) -> 36.171085 | T27: 3850 | U27: 1571 | V27: 725 | W27: 1175 | X27: 2700 | Y27: 2100 | Z27: =W27/(C27*4) -> 0.28728606 | AA27: =W27/(D27*4) -> 0.40025889 | AB27: =Y27/((C27+D27)*4) -> 0.29890685 | AC27: =X27/((C27+D27)*4) -> 0.38430881 | AD27: =AVERAGE(Z27:AC27) -> 0.34269016 | AE27: =0.31*P27+0.38*Q27+0.27*R27+0.04*S27 -> 18.043494 | AF27: =_xlfn.XLOOKUP(A27,'House Prices'!C:C,'House Prices'!Z:Z) -> 12.76 | AG27: =(K27+MEDIAN(T27:Y27)*12)/(B27*4*12) -> 0.61411964 | AH27: =_xlfn.XLOOKUP(G27,'TfL Fare'!A14:A57,'TfL Fare'!I14:I57) -> 1780
A28: Kingston upon Thames | B28: 727.4 | C28: 912.2 | D28: 574.3 | E28: 291.7 | F28: 844 | G28: Zones 3-6 | H28: 1583.5667 | I28: 1847.4944 | J28: 2111.4222 | K28: 2375.35 | L28: 2903.2056 | M28: 3431.0611 | N28: 3958.9167 | O28: 4750.7 | P28: =_xlfn.XLOOKUP(A28,'JTS0501 2022'!BY:BY,'JTS0501 2022'!BZ:BZ) -> 18.00642 | Q28: =_xlfn.XLOOKUP(A28,'JTS0501 2022'!BY:BY,'JTS0501 2022'!CI:CI) -> 13.582546 | R28: =_xlfn.XLOOKUP(A28,'JTS0501 2022'!BY:BY,'JTS0501 2022'!CR:CR) -> 10.334466 | S28: =_xlfn.XLOOKUP(A28,'JTS0501 2022'!BY:BY,'JTS0501 2022'!DA:DA) -> 27.487732 | T28: 3000 | U28: 1400 | V28: 757 | W28: 1075 | X28: 2322 | Y28: 1750 | Z28: =W28/(C28*4) -> 0.29461741 | AA28: =W28/(D28*4) -> 0.467961 | AB28: =Y28/((C28+D28)*4) -> 0.29431551 | AC28: =X28/((C28+D28)*4) -> 0.39051463 | AD28: =AVERAGE(Z28:AC28) -> 0.36185214 | AE28: =0.31*P28+0.38*Q28+0.27*R28+0.04*S28 -> 14.633172 | AF28: =_xlfn.XLOOKUP(A28,'House Prices'!C:C,'House Prices'!Z:Z) -> 12.24 | AG28: =(K28+MEDIAN(T28:Y28)*12)/(B28*4*12) -> 0.6093435 | AH28: =_xlfn.XLOOKUP(G28,'TfL Fare'!A18:A61,'TfL Fare'!I18:I61) -> 1780
A29: Waltham Forest | B29: 717.7 | C29: 804.8 | D29: 626.8 | E29: 242.5 | F29: 839.7 | G29: Zones 3-5 | H29: 1449.1467 | I29: 1690.6711 | J29: 1932.1956 | K29: 2173.72 | L29: 2656.7689 | M29: 3139.8178 | N29: 3622.8667 | O29: 4347.44 | P29: =_xlfn.XLOOKUP(A29,'JTS0501 2022'!BY:BY,'JTS0501 2022'!BZ:BZ) -> 22.606062 | Q29: =_xlfn.XLOOKUP(A29,'JTS0501 2022'!BY:BY,'JTS0501 2022'!CI:CI) -> 15.856839 | R29: =_xlfn.XLOOKUP(A29,'JTS0501 2022'!BY:BY,'JTS0501 2022'!CR:CR) -> 11.541065 | S29: =_xlfn.XLOOKUP(A29,'JTS0501 2022'!BY:BY,'JTS0501 2022'!DA:DA) -> 34.982494 | T29: 2500 | U29: 1400 | V29: 764 | W29: 1188 | X29: 2150 | Y29: 1725 | Z29: =W29/(C29*4) -> 0.36903579 | AA29: =W29/(D29*4) -> 0.47383535 | AB29: =Y29/((C29+D29)*4) -> 0.30123638 | AC29: =X29/((C29+D29)*4) -> 0.37545404 | AD29: =AVERAGE(Z29:AC29) -> 0.37989039 | AE29: =0.31*P29+0.38*Q29+0.27*R29+0.04*S29 -> 17.548865 | AF29: =_xlfn.XLOOKUP(A29,'House Prices'!C:C,'House Prices'!Z:Z) -> 11.59 | AG29: =(K29+MEDIAN(T29:Y29)*12)/(B29*4*12) -> 0.60737193 | AH29: =_xlfn.XLOOKUP(G29,'TfL Fare'!A21:A64,'TfL Fare'!I21:I64) -> £1,484
A30: Hillingdon | B30: 689.9 | C30: 762.8 | D30: 600.9 | E30: 274.3 | F30: 804.1 | G30: Zones 5-6 | H30: 1242.6067 | I30: 1449.7078 | J30: 1656.8089 | K30: 1863.91 | L30: 2278.1122 | M30: 2692.3144 | N30: 3106.5167 | O30: 3727.82 | P30: =_xlfn.XLOOKUP(A30,'JTS0501 2022'!BY:BY,'JTS0501 2022'!BZ:BZ) -> 20.318991 | Q30: =_xlfn.XLOOKUP(A30,'JTS0501 2022'!BY:BY,'JTS0501 2022'!CI:CI) -> 15.941316 | R30: =_xlfn.XLOOKUP(A30,'JTS0501 2022'!BY:BY,'JTS0501 2022'!CR:CR) -> 11.502306 | S30: =_xlfn.XLOOKUP(A30,'JTS0501 2022'!BY:BY,'JTS0501 2022'!DA:DA) -> 33.652922 | T30: 2500 | U30: 1300 | V30: 650 | W30: 1050 | X30: 1969 | Y30: 1600 | Z30: =W30/(C30*4) -> 0.3441269 | AA30: =W30/(D30*4) -> 0.43684473 | AB30: =Y30/((C30+D30)*4) -> 0.29331965 | AC30: =X30/((C30+D30)*4) -> 0.36096649 | AD30: =AVERAGE(Z30:AC30) -> 0.35881444 | AE30: =0.31*P30+0.38*Q30+0.27*R30+0.04*S30 -> 16.808327 | AF30: =_xlfn.XLOOKUP(A30,'House Prices'!C:C,'House Prices'!Z:Z) -> 11.49 | AG30: =(K30+MEDIAN(T30:Y30)*12)/(B30*4*12) -> 0.5817241 | AH30: =_xlfn.XLOOKUP(G30,'TfL Fare'!A23:A66,'TfL Fare'!I23:I66) -> £1,340
A31: Havering | B31: 710.8 | C31: 850.9 | D31: 605 | E31: 286.4 | F31: 822.5 | G31: Zone 6 only | H31: 1471.9467 | I31: 1717.2711 | J31: 1962.5956 | K31: 2207.92 | L31: 2698.5689 | M31: 3189.2178 | N31: 3679.8667 | O31: 4415.84 | P31: =_xlfn.XLOOKUP(A31,'JTS0501 2022'!BY:BY,'JTS0501 2022'!BZ:BZ) -> 25.858411 | Q31: =_xlfn.XLOOKUP(A31,'JTS0501 2022'!BY:BY,'JTS0501 2022'!CI:CI) -> 19.8499 | R31: =_xlfn.XLOOKUP(A31,'JTS0501 2022'!BY:BY,'JTS0501 2022'!CR:CR) -> 13.495924 | S31: =_xlfn.XLOOKUP(A31,'JTS0501 2022'!BY:BY,'JTS0501 2022'!DA:DA) -> 48.118614 | T31: 2400 | U31: 1250 | V31: 801 | W31: 973 | X31: 1850 | Y31: 1550 | Z31: =W31/(C31*4) -> 0.28587378 | AA31: =W31/(D31*4) -> 0.40206612 | AB31: =Y31/((C31+D31)*4) -> 0.26615839 | AC31: =X31/((C31+D31)*4) -> 0.31767292 | AD31: =AVERAGE(Z31:AC31) -> 0.3179428 | AE31: =0.31*P31+0.38*Q31+0.27*R31+0.04*S31 -> 21.127714 | AF31: =_xlfn.XLOOKUP(A31,'House Prices'!C:C,'House Prices'!Z:Z) -> 9.71 | AG31: =(K31+MEDIAN(T31:Y31)*12)/(B31*4*12) -> 0.55711639 | AH31: =_xlfn.XLOOKUP(G31,'TfL Fare'!A32:A75,'TfL Fare'!I32:I75) -> £1,340
A32: Barnet | B32: 714.6 | C32: 774.2 | D32: 671.4 | E32: 257.7 | F32: 862.4 | G32: Zones 3-4 | H32: 1295.4933 | I32: 1511.4089 | J32: 1727.3244 | K32: 1943.24 | L32: 2375.0711 | M32: 2806.9022 | N32: 3238.7333 | O32: 3886.48 | P32: =_xlfn.XLOOKUP(A32,'JTS0501 2022'!BY:BY,'JTS0501 2022'!BZ:BZ) -> 33.004479 | Q32: =_xlfn.XLOOKUP(A32,'JTS0501 2022'!BY:BY,'JTS0501 2022'!CI:CI) -> 31.029216 | R32: =_xlfn.XLOOKUP(A32,'JTS0501 2022'!BY:BY,'JTS0501 2022'!CR:CR) -> 21.41475 | S32: =_xlfn.XLOOKUP(A32,'JTS0501 2022'!BY:BY,'JTS0501 2022'!DA:DA) -> 83.405239 | T32: 2300 | U32: 1250 | V32: 800 | W32: 1000 | X32: 1950 | Y32: 1600 | Z32: =W32/(C32*4) -> 0.32291398 | AA32: =W32/(D32*4) -> 0.37235627 | AB32: =Y32/((C32+D32)*4) -> 0.27670172 | AC32: =X32/((C32+D32)*4) -> 0.33723022 | AD32: =AVERAGE(Z32:AC32) -> 0.32730054 | AE32: =0.31*P32+0.38*Q32+0.27*R32+0.04*S32 -> 31.140683 | AF32: =_xlfn.XLOOKUP(A32,'House Prices'!C:C,'House Prices'!Z:Z) -> 13.34 | AG32: =(K32+MEDIAN(T32:Y32)*12)/(B32*4*12) -> 0.55518355 | AH32: =_xlfn.XLOOKUP(G32,'TfL Fare'!A9:A52,'TfL Fare'!I9:I52) -> £1,340
A33: Croydon | B33: 721.3 | C33: 800.3 | D33: 679.5 | E33: 275 | F33: 829.8 | G33: Zones 3-6 | H33: 1577.94 | I33: 1840.93 | J33: 2103.92 | K33: 2366.91 | L33: 2892.89 | M33: 3418.87 | N33: 3944.85 | O33: 4733.82 | P33: =_xlfn.XLOOKUP(A33,'JTS0501 2022'!BY:BY,'JTS0501 2022'!BZ:BZ) -> 25.407544 | Q33: =_xlfn.XLOOKUP(A33,'JTS0501 2022'!BY:BY,'JTS0501 2022'!CI:CI) -> 18.84617 | R33: =_xlfn.XLOOKUP(A33,'JTS0501 2022'!BY:BY,'JTS0501 2022'!CR:CR) -> 13.027507 | S33: =_xlfn.XLOOKUP(A33,'JTS0501 2022'!BY:BY,'JTS0501 2022'!DA:DA) -> 44.901506 | T33: 2475 | U33: 1250 | V33: 732 | W33: 1025 | X33: 1950 | Y33: 1550 | Z33: =W33/(C33*4) -> 0.32019243 | AA33: =W33/(D33*4) -> 0.37711553 | AB33: =Y33/((C33+D33)*4) -> 0.26185971 | AC33: =X33/((C33+D33)*4) -> 0.32943641 | AD33: =AVERAGE(Z33:AC33) -> 0.32215102 | AE33: =0.31*P33+0.38*Q33+0.27*R33+0.04*S33 -> 20.35137 | AF33: =_xlfn.XLOOKUP(A33,'House Prices'!C:C,'House Prices'!Z:Z) -> 9.47 | AG33: =(K33+MEDIAN(T33:Y33)*12)/(B33*4*12) -> 0.55359854 | AH33: 1780
A34: Sutton | B34: 728.7 | C34: 814.6 | D34: 613.3 | E34: 274.4 | F34: 853.2 | G34: Zones 4-5 | H34: 1444.12 | I34: 1684.8067 | J34: 1925.4933 | K34: 2166.18 | L34: 2647.5533 | M34: 3128.9267 | N34: 3610.3 | O34: 4332.36 | P34: =_xlfn.XLOOKUP(A34,'JTS0501 2022'!BY:BY,'JTS0501 2022'!BZ:BZ) -> 20.86285 | Q34: =_xlfn.XLOOKUP(A34,'JTS0501 2022'!BY:BY,'JTS0501 2022'!CI:CI) -> 14.210073 | R34: =_xlfn.XLOOKUP(A34,'JTS0501 2022'!BY:BY,'JTS0501 2022'!CR:CR) -> 10.894269 | S34: =_xlfn.XLOOKUP(A34,'JTS0501 2022'!BY:BY,'JTS0501 2022'!DA:DA) -> 28.423714 | T34: 2500 | U34: 1250 | V34: 0 | W34: 931 | X34: 1950 | Y34: 1550 | Z34: =W34/(C34*4) -> 0.28572305 | AA34: =W34/(D34*4) -> 0.37950432 | AB34: =Y34/((C34+D34)*4) -> 0.27137755 | AC34: =X34/((C34+D34)*4) -> 0.34141046 | AD34: =AVERAGE(Z34:AC34) -> 0.31950385 | AE34: =0.31*P34+0.38*Q34+0.27*R34+0.04*S34 -> 15.945712 | AF34: =_xlfn.XLOOKUP(A34,'House Prices'!C:C,'House Prices'!Z:Z) -> 10.35 | AG34: =(K34+MEDIAN(T34:Y34)*12)/(B34*4*12) -> 0.54223789 | AH34: =_xlfn.XLOOKUP(G34,'TfL Fare'!A28:A71,'TfL Fare'!I28:I71) -> £1,340
A37: Helper | B37: Columns
A38: 266.4 | B38: 744.1
A39: 257.7 | B39: 862.4
A40: 240.7 | B40: 849.1
A41: 289.5 | B41: 747.6
A42: 252.1 | B42: 958.2
...

Sheet Sheet1

Sheet TfL Fare
A1: Column1 | B1: Column2 | C1: Column3 | D1: Column4 | E1: Column5 | F1: Column6 | G1: Column7 | H1: Column8 | I1: Column9
B2: Pay as you go caps | E2: Travelcards
A3: Zone | B3: Daily peak | C3: Daily off-peak | D3: Monday to Sunday | E3: Day anytime | F3: Day off-peak | G3: 7 Day | H3: Monthly | I3: Annual
A4: Zone 1 only | B4: £8.90 | C4: £8.90 | D4: £44.70 | E4: £16.60 | F4: £16.60 | G4: £44.70 | H4: £171.70 | I4: £1,788
A5: Zones 1-2 | B5: £8.90 | C5: £8.90 | D5: £44.70 | E5: £16.60 | F5: £16.60 | G5: £44.70 | H5: £171.70 | I5: £1,788
A6: Zones 1-3 | B6: £10.50 | C6: £10.50 | D6: £52.50 | E6: £16.60 | F6: £16.60 | G6: £52.50 | H6: £201.60 | I6: 2100
A7: Zones 1-4 | B7: £12.80 | C7: £12.80 | D7: £64.20 | E7: £16.60 | F7: £16.60 | G7: £64.20 | H7: £246.60 | I7: £2,568
A8: Zones 1-5 | B8: £15.30 | C8: £15.30 | D8: £76.40 | E8: £23.60 | F8: £16.60 | G8: £76.40 | H8: £293.40 | I8: £3,056
A9: Zones 1-6 | B9: £16.30 | C9: £16.30 | D9: £81.60 | E9: £23.60 | F9: £16.60 | G9: £81.60 | H9: £313.40 | I9: £3,264
A10: Zones 1-7 | B10: £17.80 | C10: £16.30 | D10: £88.90 | E10: £29.80 | F10: £17.80 | G10: £88.90 | H10: £341.40 | I10: £3,556
A11: Zones 1-8 | B11: £21.00 | C11: £16.30 | D11: £104.90 | E11: £29.80 | F11: £17.80 | G11: £104.90 | H11: £402.90 | I11: £4,196
A12: Zones 1-9 | B12: £23.30 | C12: £16.30 | D12: £116.40 | E12: £29.80 | F12: £17.80 | G12: £116.40 | H12: £447.00 | I12: £4,656
A13: Zone 2 only | B13: £8.90 | C13: £8.90 | D13: £33.50 | E13: £16.60 | F13: £16.60 | G13: £33.50 | H13: £128.70 | I13: 1340
A14: Zones 2-3 | B14: £10.50 | C14: £10.50 | D14: £33.50 | E14: £16.60 | F14: £16.60 | G14: £33.50 | H14: £128.70 | I14: £1,340
A15: Zones 2-4 | B15: £12.80 | C15: £12.80 | D15: £37.10 | E15: £16.60 | F15: £16.60 | G15: £37.10 | H15: £142.50 | I15: 1484
A16: Zones 2-5 | B16: £15.30 | C16: £15.30 | D16: £44.50 | E16: £23.60 | F16: £16.60 | G16: £44.50 | H16: £170.90 | I16: £1,780
A17: Zones 2-6 | B17: £16.30 | C17: £16.30 | D17: £55.90 | E17: £23.60 | F17: £16.60 | G17: £55.90 | H17: £214.70 | I17: 2236
A18: Zones 2-7 | B18: £17.80 | C18: £16.30 | D18: £57.90 | E18: £29.80 | F18: £17.80 | G18: £57.90 | H18: £222.40 | I18: £2,316
A19: Zones 2-8 | B19: £21.00 | C19: £16.30 | D19: £78.90 | E19: £29.80 | F19: £17.80 | G19: £78.90 | H19: £303.00 | I19: £3,156
A20: Zones 2-9 | B20: £23.30 | C20: £16.30 | D20: £78.90 | E20: £29.80 | F20: £17.80 | G20: £78.90 | H20: £303.00 | I20: £3,156
A21: Zone 3 only | B21: £10.50 | C21: £10.50 | D21: £33.50 | E21: £16.60 | F21: £16.60 | G21: £33.50 | H21: £128.70 | I21: £1,340
A22: Zones 3-4 | B22: £12.80 | C22: £12.80 | D22: £33.50 | E22: £16.60 | F22: £16.60 | G22: £33.50 | H22: £128.70 | I22: £1,340
A23: Zones 3-5 | B23: £15.30 | C23: £15.30 | D23: £37.10 | E23: £23.60 | F23: £16.60 | G23: £37.10 | H23: £142.50 | I23: £1,484
A24: Zones 3-6 | B24: £16.30 | C24: £16.30 | D24: £44.50 | E24: £23.60 | F24: £16.60 | G24: £44.50 | H24: £170.90 | I24: 1780
A25: Zones 3-7 | B25: £17.80 | C25: £16.30 | D25: £57.90 | E25: £29.80 | F25: £17.80 | G25: £57.90 | H25: £222.40 | I25: £2,316
A26: Zones 3-8 | B26: £21.00 | C26: £16.30 | D26: £78.90 | E26: £29.80 | F26: £17.80 | G26: £78.90 | H26: £303.00 | I26: £3,156
A27: Zones 3-9 | B27: £23.30 | C27: £16.30 | D27: £78.90 | E27: £29.80 | F27: £17.80 | G27: £78.90 | H27: £303.00 | I27: £3,156
A28: Zone 4 only | B28: £12.80 | C28: £12.80 | D28: £33.50 | E28: £16.60 | F28: £16.60 | G28: £33.50 | H28: £128.70 | I28: £1,340
A29: Zones 4-5 | B29: £15.30 | C29: £15.30 | D29: £33.50 | E29: £23.60 | F29: £16.60 | G29: £33.50 | H29: £128.70 | I29: £1,340
A30: Zones 4-6 | B30: £16.30 | C30: £16.30 | D30: £37.10 | E30: £23.60 | F30: £16.60 | G30: £37.10 | H30: £142.50 | I30: 1484
A31: Zones 4-7 | B31: £17.80 | C31: £16.30 | D31: £41.90 | E31: £29.80 | F31: £17.80 | G31: £41.90 | H31: £160.90 | I31: £1,676
A32: Zones 4-8 | B32: £21.00 | C32: £16.30 | D32: £70.70 | E32: £29.80 | F32: £17.80 | G32: £70.70 | H32: £271.50 | I32: £2,828
A33: Zones 4-9 | B33: £23.30 | C33: £16.30 | D33: £70.70 | E33: £29.80 | F33: £17.80 | G33: £70.70 | H33: £271.50 | I33: £2,828
A34: Zone 5 only | B34: £15.30 | C34: £15.30 | D34: £33.50 | E34: £23.60 | F34: £16.60 | G34: £33.50 | H34: £128.70 | I34: £1,340
A35: Zones 5-6 | B35: £16.30 | C35: £16.30 | D35: £33.50 | E35: £23.60 | F35: £16.60 | G35: £33.50 | H35: £128.70 | I35: £1,340
A36: Zones 5-7 | B36: £17.80 | C36: £16.30 | D36: £41.90 | E36: £29.80 | F36: £17.80 | G36: £41.90 | H36: £160.90 | I36: £1,676
A37: Zones 5-8 | B37: £21.00 | C37: £16.30 | D37: £70.70 | E37: £29.80 | F37: £17.80 | G37: £70.70 | H37: £271.50 | I37: £2,828
A38: Zones 5-9 | B38: £23.30 | C38: £16.30 | D38: £70.70 | E38: £29.80 | F38: £17.80 | G38: £70.70 | H38: £271.50 | I38: £2,828
A39: Zone 6 only | B39: £16.30 | C39: £16.30 | D39: £33.50 | E39: £23.60 | F39: £16.60 | G39: £33.50 | H39: £128.70 | I39: £1,340
A40: Zones 6-7 | B40: £17.80 | C40: £16.30 | D40: £41.90 | E40: £29.80 | F40: £17.80 | G40: £41.90 | H40: £160.90 | I40: £1,676
...

Sheet House Prices
A1: New Code | B1: Old Code | C1: Area | D1: 2002 | E1: 2003 | F1: 2004 | G1: 2005 | H1: 2006 | I1: 2007 | J1: 2008 | K1: 2009 | L1: 2010 | M1: 2011 | N1: 2012 | O1: 2013 | P1: 2014 | Q1: 2015 | R1: 2016 | S1: 2017 | T1: 2018 | U1: 2019 | V1: 2020 | W1: 2021 | X1: 2022 | Y1: 2023 | Z1: 2024
A3: E09000001 | B3: 00AA | C3: City of London | D3: 6.29 | E3: [x] | F3: [x] | G3: [x] | H3: [x] | I3: [x] | J3: [x] | K3: 9.52 | L3: [x] | M3: 8.66 | N3: [x] | O3: [x] | P3: [x] | Q3: [x] | R3: 14.83 | S3: [x] | T3: 16.49 | U3: [x] | V3: [x] | W3: [x] | X3: 16.07 | Y3: [x] | Z3: [x]
A4: E09000002 | B4: 00AB | C4: Barking and Dagenham | D4: 4.68 | E4: 6.26 | F4: 7.18 | G4: 7.15 | H4: 6.55 | I4: 7.05 | J4: 7.46 | K4: 5.71 | L4: 6.3 | M4: 6.56 | N4: 6.38 | O4: 6.28 | P4: 7.54 | Q4: 8.24 | R4: 9.89 | S4: 10 | T4: 10.4 | U4: 10.74 | V4: 9.74 | W4: 10.25 | X4: 10.76 | Y4: 10.89 | Z4: 9.52
A5: E09000003 | B5: 00AC | C5: Barnet | D5: 7.42 | E5: 8.49 | F5: 8.64 | G5: 8.46 | H5: 9.12 | I5: 9.83 | J5: 9.16 | K5: 8.47 | L5: 9.72 | M5: 10.06 | N5: 10.05 | O5: 10.16 | P5: 12.14 | Q5: 13.3 | R5: 14.05 | S5: 13.7 | T5: 14.45 | U5: 14.19 | V5: 15.17 | W5: 16.01 | X5: 15.68 | Y5: 13.42 | Z5: 13.34
A6: E09000004 | B6: 00AD | C6: Bexley | D6: 5.56 | E6: 6.29 | F6: 6.57 | G6: 6.73 | H6: 6.79 | I6: 7.19 | J6: 6.97 | K6: 6.29 | L6: 6.72 | M6: 6.77 | N6: 6.53 | O6: 6.68 | P6: 7.69 | Q6: 8.47 | R6: 9.44 | S6: 10.01 | T6: 10.04 | U6: 9.61 | V6: 9.18 | W6: 10.44 | X6: 9.98 | Y6: 9.75 | Z6: 9.41
A7: E09000005 | B7: 00AE | C7: Brent | D7: 8.1 | E7: 9.32 | F7: 9.26 | G7: 9.59 | H7: 9.85 | I7: 10.8 | J7: 9.89 | K7: 9.75 | L7: 10.31 | M7: 11.19 | N7: 11.13 | O7: 12.13 | P7: 12.36 | Q7: 13.43 | R7: 15.21 | S7: 15.65 | T7: 16.32 | U7: 15.59 | V7: 14.34 | W7: 15.24 | X7: 14.67 | Y7: 14.56 | Z7: 14.18
A8: E09000006 | B8: 00AF | C8: Bromley | D8: 6.48 | E8: 7.13 | F8: 7.54 | G8: 7.45 | H8: 7.54 | I8: 7.71 | J8: 7.49 | K8: 6.99 | L8: 7.82 | M8: 8.06 | N8: 7.64 | O8: 7.94 | P8: 8.92 | Q8: 9.93 | R8: 10.86 | S8: 10.83 | T8: 11 | U8: 10.73 | V8: 10.3 | W8: 11.95 | X8: 11.47 | Y8: 10.82 | Z8: 10.56
A9: E09000007 | B9: 00AG | C9: Camden | D9: 9.71 | E9: 9.24 | F9: 10.4 | G9: 10.29 | H9: 10.38 | I9: 11.4 | J9: 11.97 | K9: 11.15 | L9: 12.63 | M9: 13.96 | N9: 13.3 | O9: 15.15 | P9: 17.43 | Q9: 17.17 | R9: 18.51 | S9: 19.4 | T9: 18.23 | U9: 18.27 | V9: 19.12 | W9: 19.5 | X9: 19.68 | Y9: 17.77 | Z9: 16.84
A10: E09000008 | B10: 00AH | C10: Croydon | D10: 5.82 | E10: 6.6 | F10: 7.23 | G10: 7.35 | H10: 7.38 | I10: 7.96 | J10: 7.82 | K10: 6.8 | L10: 7.17 | M10: 7.27 | N10: 7.41 | O10: 7.54 | P10: 7.82 | Q10: 8.98 | R10: 10.18 | S10: 10.73 | T10: 10.46 | U10: 10.95 | V10: 10.29 | W10: 11.35 | X10: 10.83 | Y10: 10.19 | Z10: 9.47
A11: E09000009 | B11: 00AJ | C11: Ealing | D11: 7.09 | E11: 8.47 | F11: 8.68 | G11: 8.96 | H11: 8.88 | I11: 9.22 | J11: 9.66 | K11: 8.07 | L11: 9.61 | M11: 9.42 | N11: 9.94 | O11: 10.93 | P11: 12.28 | Q11: 14.34 | R11: 14.73 | S11: 14.88 | T11: 14.16 | U11: 14.79 | V11: 13.29 | W11: 14.64 | X11: 14.57 | Y11: 13.54 | Z11: 12.81
A12: E09000010 | B12: 00AK | C12: Enfield | D12: 6.03 | E12: 7.38 | F12: 7.31 | G12: 7.83 | H12: 7.75 | I12: 8.17 | J12: 8.44 | K12: 7.76 | L12: 8 | M12: 8.26 | N12: 8.26 | O12: 8.43 | P12: 9.16 | Q12: 10.35 | R12: 12.16 | S12: 13 | T12: 12.94 | U12: 12.34 | V12: 12.69 | W12: 12.84 | X12: 12.46 | Y12: 11.8 | Z12: 10.59
A13: E09000011 | B13: 00AL | C13: Greenwich | D13: 5.99 | E13: 6.37 | F13: 6.86 | G13: 7.41 | H13: 7.7 | I13: 7.53 | J13: 7.88 | K13: 6.74 | L13: 7.61 | M13: 8.17 | N13: 7.96 | O13: 8.1 | P13: 10.09 | Q13: 10.57 | R13: 11.87 | S13: 12.67 | T13: 11.95 | U13: 12.73 | V13: 12.18 | W13: 12.92 | X13: 12.51 | Y13: 11.67 | Z13: 10.09
A14: E09000012 | B14: 00AM | C14: Hackney | D14: 7.37 | E14: 8.15 | F14: 8.7 | G14: 8.25 | H14: 9.48 | I14: 9.04 | J14: 9.06 | K14: 8.91 | L14: 9.57 | M14: 9.21 | N14: 10.41 | O14: 11.42 | P14: 12.82 | Q14: 14.36 | R14: 16.67 | S14: 15.22 | T14: 16.34 | U14: 16.04 | V14: 17.34 | W14: 16.52 | X14: 14.54 | Y14: 14.04 | Z14: 12.63
A15: E09000013 | B15: 00AN | C15: Hammersmith and Fulham | D15: 8.55 | E15: 9.31 | F15: 9.82 | G15: 10.8 | H15: 10.8 | I15: 11.67 | J15: 11.76 | K15: 11.07 | L15: 12.36 | M15: 13.11 | N15: 12.48 | O15: 14.45 | P15: 16.95 | Q15: 19.28 | R15: 19.21 | S15: 19.08 | T15: 20.04 | U15: 17.28 | V15: 18.84 | W15: 19.46 | X15: 18.39 | Y15: 17.72 | Z15: 15.83
... A35: E09000033 | B35: 00BK | C35: Westminster | D35: 11.01 | E35: 11.41 | F35: 10.6 | G35: 11.3 | H35: 12.32 | I35: 12.86 | J35: 12.93 | K35: 13.27 | L35: 12.15 | M35: 14.61 | N35: 14.16 | O35: 18.69 | P35: 20.38 | Q35: 20.54 | R35: 23.48 | S35: 24.77 | T35: 23.71 | U35: 21.35 | V35: 22.45 | W35: 21.49 | X35: 24.29 | Y35: 20.9 | Z35: 18.31

Sheet Relevant Rental Data
A1: Borough | B1: Bedroom Category | C1: Count of rents | D1: Mean | E1: Lower quartile | F1: Median | G1: Upper quartile | I1: Sum of Median | J1: Column Labels
A2: Barking and Dagenham | B2: Room | C2: 10 | D2: 646 | E2: =0 -> 0 | F2: 726 | G2: =0 -> 0 | I2: Borough | J2: Four or More Bedrooms | K2: One Bedroom | L2: Room | M2: Studio | N2: Three Bedrooms | O2: Two Bedrooms | P2: Grand Total
A3: Barking and Dagenham | B3: Studio | C3: - | D3: =0 -> 0 | E3: =0 -> 0 | F3: =0 -> 0 | G3: =0 -> 0 | I3: Barking and Dagenham | J3: 2400 | K3: 1350 | L3: 726 | M3: 0 | N3: 1965 | O3: 1700 | P3: 8141
A4: Barking and Dagenham | B4: One Bedroom | C4: 200 | D4: 1341 | E4: 1250 | F4: 1350 | G4: 1480 | I4: Barnet | J4: 3150 | K4: 1450 | L4: 726 | M4: 1100 | N4: 2400 | O4: 1750 | P4: 10576
A5: Barking and Dagenham | B5: Two Bedrooms | C5: 390 | D5: 1660 | E5: 1500 | F5: 1700 | G5: 1836 | I5: Bexley | J5: 2300 | K5: 1250 | L5: 800 | M5: 1000 | N5: 1950 | O5: 1600 | P5: 8900
A6: Barking and Dagenham | B6: Three Bedrooms | C6: 190 | D6: 1954 | E6: 1750 | F6: 1965 | G6: 2100 | I6: Brent | J6: 3200 | K6: 1650 | L6: 776 | M6: 1160 | N6: 2400 | O6: 2000 | P6: 11186
A7: Barking and Dagenham | B7: Four or More Bedrooms | C7: 20 | D7: 2409 | E7: 2300 | F7: 2400 | G7: 2500 | I7: Bromley | J7: 2500 | K7: 1300 | L7: 718 | M7: 995 | N7: 2000 | O7: 1600 | P7: 9113
A8: Barnet | B8: Room | C8: 10 | D8: 747 | E8: 701 | F8: 726 | G8: 796 | I8: Camden | J8: 4090 | K8: 2000 | L8: 875 | M8: 1450 | N8: 3500 | O8: 2600 | P8: 14515
A9: Barnet | B9: Studio | C9: 110 | D9: 1105 | E9: 1000 | F9: 1100 | G9: 1200 | I9: City of London | J9: 0 | K9: 2300 | L9: 0 | M9: 2300 | N9: 4575 | O9: 3075 | P9: 12250
A10: Barnet | B10: One Bedroom | C10: 670 | D10: 1472 | E10: 1300 | F10: 1450 | G10: 1600 | I10: Croydon | J10: 2475 | K10: 1250 | L10: 732 | M10: 1025 | N10: 1950 | O10: 1550 | P10: 8982
A11: Barnet | B11: Two Bedrooms | C11: 1150 | D11: 1802 | E11: 1600 | F11: 1750 | G11: 1975 | I11: Ealing | J11: 2900 | K11: 1550 | L11: 826 | M11: 1345 | N11: 2445 | O11: 1900 | P11: 10966
A12: Barnet | B12: Three Bedrooms | C12: 430 | D12: 2448 | E12: 2100 | F12: 2400 | G12: 2700 | I12: Enfield | J12: 2900 | K12: 1350 | L12: 738 | M12: 1100 | N12: 2050 | O12: 1650 | P12: 9788
A13: Barnet | B13: Four or More Bedrooms | C13: 160 | D13: 3398 | E13: 2800 | F13: 3150 | G13: 3775 | I13: Greenwich | J13: 2750 | K13: 1525 | L13: 770 | M13: 1150 | N13: 2100 | O13: 1850 | P13: 10145
A14: Bexley | B14: Room | C14: 20 | D14: 833 | E14: 738 | F14: 800 | G14: 1000 | I14: Hackney | J14: 3950 | K14: 2000 | L14: 976 | M14: 1280 | N14: 3200 | O14: 2500 | P14: 13906
A15: Bexley | B15: Studio | C15: 10 | D15: 1081 | E15: =0 -> 0 | F15: 1000 | G15: =0 -> 0 | I15: Hammersmith and Fulham | J15: 4600 | K15: 1850 | L15: 1026 | M15: 1500 | N15: 3300 | O15: 2250 | P15: 14526
A16: Bexley | B16: One Bedroom | C16: 180 | D16: 1248 | E16: 1100 | F16: 1250 | G16: 1375 | I16: Haringey | J16: 3350 | K16: 1625 | L16: 686 | M16: 1067 | N16: 2500 | O16: 1993 | P16: 11221
A17: Bexley | B17: Two Bedrooms | C17: 300 | D17: 1554 | E17: 1400 | F17: 1600 | G17: 1700 | I17: Harrow | J17: 2800 | K17: 1400 | L17: 826 | M17: 1088 | N17: 2150 | O17: 1700 | P17: 9964
A18: Bexley | B18: Three Bedrooms | C18: 220 | D18: 1924 | E18: 1750 | F18: 1950 | G18: 2100 | I18: Havering | J18: 2400 | K18: 1250 | L18: 801 | M18: 973 | N18: 1850 | O18: 1550 | P18: 8824
A19: Bexley | B19: Four or More Bedrooms | C19: 50 | D19: 2315 | E19: 2050 | F19: 2300 | G19: 2600 | I19: Hillingdon | J19: 2500 | K19: 1300 | L19: 650 | M19: 1050 | N19: 1969 | O19: 1600 | P19: 9069
A20: Brent | B20: Room | C20: 80 | D20: 796 | E20: 708 | F20: 776 | G20: 878 | I20: Hounslow | J20: 3100 | K20: 1495 | L20: 700 | M20: 1150 | N20: 2250 | O20: 1800 | P20: 10495
A21: Brent | B21: Studio | C21: 110 | D21: 1152 | E21: 1000 | F21: 1160 | G21: 1280 | I21: Islington | J21: 4500 | K21: 2000 | L21: 895 | M21: 1400 | N21: 3100 | O21: 2525 | P21: 14420
A22: Brent | B22: One Bedroom | C22: 440 | D22: 1646 | E22: 1450 | F22: 1650 | G22: 1850 | I22: Kensington and Chelsea | J22: 8000 | K22: 2396 | L22: 1177 | M22: 1603 | N22: 5688 | O22: 3358 | P22: 22222
A23: Brent | B23: Two Bedrooms | C23: 660 | D23: 2036 | E23: 1800 | F23: 2000 | G23: 2250 | I23: Kingston upon Thames | J23: 3000 | K23: 1400 | L23: 757 | M23: 1075 | N23: 2322 | O23: 1750 | P23: 10304
A24: Brent | B24: Three Bedrooms | C24: 290 | D24: 2480 | E24: 2100 | F24: 2400 | G24: 2700 | I24: Lambeth | J24: 3750 | K24: 1800 | L24: 830 | M24: 1375 | N24: 2850 | O24: 2205 | P24: 12810
A25: Brent | B25: Four or More Bedrooms | C25: 120 | D25: 3601 | E25: 2515 | F25: 3200 | G25: 4213 | I25: Lewisham | J25: 2900 | K25: 1450 | L25: 821 | M25: 1150 | N25: 2200 | O25: 1750 | P25: 10271
A26: Bromley | B26: Room | C26: 20 | D26: 706 | E26: 676 | F26: 718 | G26: 801 | I26: Merton | J26: 3350 | K26: 1500 | L26: 824 | M26: 1388 | N26: 2450 | O26: 1750 | P26: 11262
A27: Bromley | B27: Studio | C27: 40 | D27: 993 | E27: 925 | F27: 995 | G27: 1050 | I27: Newham | J27: 2525 | K27: 1650 | L27: 701 | M27: 1380 | N27: 2200 | O27: 1950 | P27: 10406
... A36: Camden | B36: Three Bedrooms | C36: 130 | D36: 3684 | E36: 3025 | F36: 3500 | G36: 4000 | I36: Grand Total | J36: 111915 | K36: 53504 | L36: 25588 | M36: 40543 | N36: 87272 | O36: 67139 | P36: 385961
A37: Camden | B37: Four or More Bedrooms | C37: 40 | D37: 4815 | E37: 3590 | F37: 4090 | G37: 5079
A38: City of London | B38: Room | C38: - | D38: =0 -> 0 | E38: =0 -> 0 | F38: =0 -> 0 | G38: =0 -> 0
A39: City of London | B39: Studio | C39: 10 | D39: 2388 | E39: =0 -> 0 | F39: 2300 | G39: =0 -> 0
A40: City of London | B40: One Bedroom | C40: 70 | D40: 2395 | E40: 2100 | F40: 2300 | G40: 2675
A41: City of London | B41: Two Bedrooms | C41: 50 | D41: 3072 | E41: 2843 | F41: 3075 | G41: 3263
A42: City of London | B42: Three Bedrooms | C42: 10 | D42: 4378 | E42: =0 -> 0 | F42: 4575 | G42: =0 -> 0
A43: City of London | B43: Four or More Bedrooms | C43: - | D43: =0 -> 0 | E43: =0 -> 0 | F43: =0 -> 0 | G43: =0 -> 0
A44: Croydon | B44: Room | C44: 20 | D44: 719 | E44: 650 | F44: 732 | G44: 805
A45: Croydon | B45: Studio | C45: 50 | D45: 1019 | E45: 938 | F45: 1025 | G45: 1100
A46: Croydon | B46: One Bedroom | C46: 540 | D46: 1226 | E46: 1100 | F46: 1250 | G46: 1315
A47: Croydon | B47: Two Bedrooms | C47: 810 | D47: 1542 | E47: 1400 | F47: 1550 | G47: 1650
A48: Croydon | B48: Three Bedrooms | C48: 350 | D48: 1932 | E48: 1700 | F48: 1950 | G48: 2150
...

Sheet Sheet15
A1: Year | B1: Public transport | C1: Private transport | D1: Cycle | E1: Walk
A2: -2000 | B2: -0.27 | C2: -0.48 | D2: -0.012 | E2: -0.24
A3: 2013 | B3: 0.36 | C3: 0.38 | D3: 0.019 | E3: 0.24
A4: 2014 | B4: 0.36 | C4: 0.38 | D4: 0.021 | E4: 0.24
A5: 2015 | B5: 0.35 | C5: 0.37 | D5: 0.037 | E5: 0.24
A6: 2016 | B6: 0.35 | C6: 0.37 | D6: 0.036 | E6: 0.24
A7: 2017 | B7: 0.35 | C7: 0.37 | D7: 0.037 | E7: 0.24
A8: 2018 | B8: 0.35 | C8: 0.37 | D8: 0.037 | E8: 0.25
A9: 2019 | B9: 0.35 | C9: 0.36 | D9: 0.036 | E9: 0.25
A10: 2020 | B10: 0.22 | C10: 0.39 | D10: 0.061 | E10: 0.33
A11: 2021 | B11: 0.23 | C11: 0.42 | D11: 0.04 | E11: 0.31
A12: 2022 | B12: 0.31 | C12: 0.38 | D12: 0.045 | E12: 0.27

Sheet Rent June 2025
A1: Summary of monthly rents recorded between July 2024 to June 2025 by borough and bedroom category for London [note 1, 2, 3, 4 ,5 ,6 ,7]
A2: This worksheet contains one table. Some cells refer to notes that can be found within the notes worksheet.
A3: Borough | B3: Bedroom Category | C3: Count of rents | D3: Mean | E3: Lower quartile | F3: Median | G3: Upper quartile
A4: Barking and Dagenham | B4: Room | C4: 10 | D4: 646 | E4: .. | F4: 726 | G4: ..
A5: Barking and Dagenham | B5: Studio | C5: - | D5: .. | E5: .. | F5: .. | G5: ..
A6: Barking and Dagenham | B6: One Bedroom | C6: 200 | D6: 1341 | E6: 1250 | F6: 1350 | G6: 1480
A7: Barking and Dagenham | B7: Two Bedrooms | C7: 390 | D7: 1660 | E7: 1500 | F7: 1700 | G7: 1836
A8: Barking and Dagenham | B8: Three Bedrooms | C8: 190 | D8: 1954 | E8: 1750 | F8: 1965 | G8: 2100
A9: Barking and Dagenham | B9: Four or More Bedrooms | C9: 20 | D9: 2409 | E9: 2300 | F9: 2400 | G9: 2500
A10: Barnet | B10: Room | C10: 10 | D10: 747 | E10: 701 | F10: 726 | G10: 796
A11: Barnet | B11: Studio | C11: 110 | D11: 1105 | E11: 1000 | F11: 1100 | G11: 1200
A12: Barnet | B12: One Bedroom | C12: 670 | D12: 1472 | E12: 1300 | F12: 1450 | G12: 1600
A13: Barnet | B13: Two Bedrooms | C13: 1150 | D13: 1802 | E13: 1600 | F13: 1750 | G13: 1975
A14: Barnet | B14: Three Bedrooms | C14: 430 | D14: 2448 | E14: 2100 | F14: 2400 | G14: 2700
A15: Barnet | B15: Four or More Bedrooms | C15: 160 | D15: 3398 | E15: 2800 | F15: 3150 | G15: 3775
A16: Bexley | B16: Room | C16: 20 | D16: 833 | E16: 738 | F16: 800 | G16: 1000
A17: Bexley | B17: Studio | C17: 10 | D17: 1081 | E17: .. | F17: 1000 | G17: ..
A18: Bexley | B18: One Bedroom | C18: 180 | D18: 1248 | E18: 1100 | F18: 1250 | G18: 1375
